<mujoco model="wheel_legged_model.SLDASM">
  <default>
    <default class="robot">
      <default class="motor">
        <joint />
        <motor />
      </default>
      <default class="visual">
        <geom material="visualgeom" contype="0" conaffinity="0" group="2" />
      </default>
      <default class="collision">
        <geom material="collision_material" condim="3" contype="0" conaffinity="1" priority="1" group="1" solref="0.005 1" solimp="0.99 0.999 1e-05" friction="1 0.01 0.01" />
      </default>
    </default>
  </default>

  <compiler angle="radian" />
  <option timestep="0.0001" integrator="RK4" solver="Newton" cone="elliptic" iterations="100" tolerance="1e-10" impratio="10" />

  <asset>
    <material name="visualgeom" rgba="0.792156862745098 0.819607843137255 0.933333333333333 1" />
    <material name="default_material" rgba="0.7 0.7 0.7 1" />
    <material name="collision_material" rgba="1.0 0.28 0.1 0.9" />
    <texture name="grid" type="2d" builtin="checker" width="512" height="512" rgb1=".1 .2 .3" rgb2=".2 .3 .4" />
    <material name="grid" texture="grid" texrepeat="1 1" texuniform="true" reflectance=".2" />
    <mesh name="base_link.STL" file="meshes/base_link.STL" />
    <mesh name="left_front_l.STL" file="meshes/left_front_l.STL" />
    <mesh name="left_front_1_l.STL" file="meshes/left_front_1_l.STL" />
    <mesh name="left_front_2_l.STL" file="meshes/left_front_2_l.STL" />
    <mesh name="left_front_3_l.STL" file="meshes/left_front_3_l.STL" />
    <mesh name="left_behind_l.STL" file="meshes/left_behind_l.STL" />
    <mesh name="left_behind_withwheel_l.STL" file="meshes/left_behind_withwheel_l.STL" />
    <mesh name="left_wheel_l.STL" file="meshes/left_wheel_l.STL" />
    <mesh name="right_behind_l.STL" file="meshes/right_behind_l.STL" />
    <mesh name="right_behind_withwheel_l.STL" file="meshes/right_behind_withwheel_l.STL" />
    <mesh name="right_wheel_l.STL" file="meshes/right_wheel_l.STL" />
    <mesh name="right_front_l.STL" file="meshes/right_front_l.STL" />
    <mesh name="right_front_1_l.STL" file="meshes/right_front_1_l.STL" />
    <mesh name="right_front_2_l.STL" file="meshes/right_front_2_l.STL" />
    <mesh name="right_front_3_l.STL" file="meshes/right_front_3_l.STL" />
    <mesh name="gimbal_yaw_l.STL" file="meshes/gimbal_yaw_l.STL" />
    <mesh name="pitch_l.STL" file="meshes/pitch_l.STL" />
    <mesh name="pitch_1_l.STL" file="meshes/pitch_1_l.STL" />
    <mesh name="pitch_2_l.STL" file="meshes/pitch_2_l.STL" />
  </asset>

  <worldbody>
    <light diffuse="0.3 0.3 0.3" pos="1 0 3" dir="-1 0 -3" />
    <geom type="plane" size="10 10 0.01"  material="grid" />
    
    <body name="base_link" pos="0.00000000 0.00000000 0.3814554" quat="1 0 0 0" childclass="robot">
    <inertial pos="0.010311 -0.002804 0.052579" quat="0.0192815 0.704315 -0.012772 0.70951" mass="12.14" diaginertia="0.365833 0.246926 0.200328"/>
      <freejoint name="floating_base" />
      <geom name="base_link_collision" pos="0 0 0" quat="1.0 0.0 0.0 0.0" type="mesh" mesh="base_link.STL" class="collision" />
      <geom name="base_link_visual" pos="0 0 0" quat="1.0 0.0 0.0 0.0" material="" type="mesh" mesh="base_link.STL" class="visual" />
      <body name="left_front_l" pos="0 0.167999999999998 0.109926406871126" quat="0.7071067811865464 -0.7071067811865488 0.0 0.0">
        <joint name="left_front_j" type="hinge" ref="0.0" class="motor" axis="0 0 1" range="0 1.5"/>
        <inertial pos="0.0407144371761395 0.004705922364367 0.00475543589285732" quat="1.0 0.0 0.0 0.0" mass="0.0394619339059221" diaginertia="4.71324990426048e-06 4.81433551348553e-05 5.21135509591295e-05" />
        <geom name="left_front_l_collision" pos="0 0 0" quat="1.0 0.0 0.0 0.0" type="mesh" mesh="left_front_l.STL" class="collision" />
        <geom name="left_front_l_visual" pos="0 0 0" quat="1.0 0.0 0.0 0.0" material="" type="mesh" mesh="left_front_l.STL" class="visual" />
        <body name="left_front_1_l" pos="0.0973518677179026 0.0112522820719916 -0.00320000000029091" quat="1.0 0.0 0.0 0.0">
          <joint name="left_front_1_j" type="hinge" ref="0.0" class="motor" axis="0 0 1" range="-0.5 1"/>
          <inertial pos="-0.0470169207870499 0.0350400744014973 -0.00400907229238207" quat="1.0 0.0 0.0 0.0" mass="0.0174981792263048" diaginertia="1.04929958937463e-05 1.83575665530197e-05 2.86647012418916e-05" />
          <geom name="left_front_1_l_collision" pos="0 0 0" quat="1.0 0.0 0.0 0.0" type="mesh" mesh="left_front_1_l.STL" class="collision" />
          <geom name="left_front_1_l_visual" pos="0 0 0" quat="1.0 0.0 0.0 0.0" material="" type="mesh" mesh="left_front_1_l.STL" class="visual" />
          <body name="left_front_2_l" pos="-0.0938127774247035 0.0699153973876011 0.00990000000011584" quat="1.0 0.0 0.0 0.0">
            <joint name="left_front_2_j" type="hinge" ref="0.0" class="motor" axis="0 0 -1" range="-1 0.5"/>
            <inertial pos="-0.075183690970079 -0.0504703536541004 -0.00399999999979461" quat="1.0 0.0 0.0 0.0" mass="0.0370037657795749" diaginertia="4.50013223051723e-05 8.44866833386059e-05 0.000129093298808796" />
            <geom name="left_front_2_l_collision" pos="0 0 0" quat="1.0 0.0 0.0 0.0" type="mesh" mesh="left_front_2_l.STL" class="collision" />
            <geom name="left_front_2_l_visual" pos="0 0 0" quat="1.0 0.0 0.0 0.0" material="" type="mesh" mesh="left_front_2_l.STL" class="visual" />
	    <site name="left_front__withbehind_site" pos="-0.09971 -0.06234 0" size="0.01" rgba="1 0 0 1"/>

            <body name="left_front_3_l" pos="-0.147178920234087 -0.108204003042513 -0.00989999999965879" quat="1.0 0.0 0.0 0.0">
              <joint name="left_front_3_j" type="hinge" ref="0.0" class="motor" axis="0 0 -1" />
              <inertial pos="-0.0572754539807334 0.0112099385870263 -0.00400907229285483" quat="1.0 0.0 0.0 0.0" mass="0.0174981792263048" diaginertia="1.68278889954112e-06 2.71677735472247e-05 2.86647012418915e-05" />
              <geom name="left_front_3_l_collision" pos="0 0 0" quat="1.0 0.0 0.0 0.0" type="mesh" mesh="left_front_3_l.STL" class="collision" />
              <geom name="left_front_3_l_visual" pos="0 0 0" quat="1.0 0.0 0.0 0.0" material="" type="mesh" mesh="left_front_3_l.STL" class="visual" />
	      <site name="left_front__withwheel_site" pos="-0.11482 0.02247 0" size="0.01" rgba="1 0 0 1"/>

            </body>
          </body>
        </body>
      </body>
      <body name="left_behind_l" pos="0 0.164500000000024 0.109926406871198" quat="0.7071067811865464 -0.7071067811865488 0.0 0.0">
        <joint name="left_behind_j" type="hinge" ref="0.0" class="motor" axis="0 0 -1" range="0 1.5"/>
        <inertial pos="-0.096408174866808 0.0181673344416381 -0.00511795868036391" quat="1.0 0.0 0.0 0.0" mass="0.15401643822471" diaginertia="6.73819049653811e-05 0.000716413578770048 0.000777601605408999" />
        <geom name="left_behind_l_collision" pos="0 0 0" quat="1.0 0.0 0.0 0.0" type="mesh" mesh="left_behind_l.STL" class="collision" />
        <geom name="left_behind_l_visual" pos="0 0 0" quat="1.0 0.0 0.0 0.0" material="" type="mesh" mesh="left_behind_l.STL" class="visual" />
	<site name="left_behind__withfront_site" pos="-0.09618 0.01882 0" size="0.01" rgba="1 0 0 1"/>

        <body name="left_behind_withwheel_l" pos="-0.210996732793725 0.0412962316714347 0.0144999999996798" quat="1.0 0.0 0.0 0.0">
          <joint name="left_behind_withwheel_j" type="hinge" ref="0.0" class="motor" axis="0 0 -1" range="-1.5 1"/>
          <inertial pos="0.100352140248059 0.0616991997716945 -0.0060021950425008" quat="1.0 0.0 0.0 0.0" mass="0.185679521185983" diaginertia="0.000540916412036633 0.00122217383188718 0.00175863230690654" />
          <geom name="left_behind_withwheel_l_collision" pos="0 0 0" quat="1.0 0.0 0.0 0.0" type="mesh" mesh="left_behind_withwheel_l.STL" class="collision" />
          <geom name="left_behind_withwheel_l_visual" pos="0 0 0" quat="1.0 0.0 0.0 0.0" material="" type="mesh" mesh="left_behind_withwheel_l.STL" class="visual" />
	  <site name="left_behind__withwheel_site" pos="-0.04746 -0.04586 0" size="0.01" rgba="1 0 0 1"/>

          <body name="left_wheel_l" pos="0.218761063539191 0.136775718163465 0.0335500000005559" quat="1.0 0.0 0.0 0.0">
            <joint name="left_wheel_j" type="hinge" ref="0.0" class="motor" axis="0 0 -1" />
            <inertial pos="4.36584761490319E-05 0.000117342074660659 -0.0154850656142491" quat="1.0 0.0 0.0 0.0" mass="0.323730705782694" diaginertia="0.000297895509749632 0.000298554738662778 0.000520427201505402" />
            <geom name="left_wheel_l_collision" pos="0 0 0" quat="1.0 0.0 0.0 0.0" type="cylinder" size="0.06 0.02" class="collision" />
            <geom name="left_wheel_l_visual" pos="0 0 0" quat="1.0 0.0 0.0 0.0" material="" type="mesh" mesh="left_wheel_l.STL" class="visual" />
          </body>
        </body>
      </body>
      <body name="right_behind_l" pos="0 -0.164500000000031 0.109926406871237" quat="0.7071067811865464 0.7071067811865488 0.0 0.0">
        <joint name="right_behind_j" type="hinge" ref="0.0" class="motor" axis="0 0 1" range="0 1.5"/>
        <inertial pos="-0.096940106479049 -0.0150732868908536 -0.0051179586803639" quat="1.0 0.0 0.0 0.0" mass="0.154016438224709" diaginertia="6.07479803325217e-05 0.000723047503402907 0.000777601605408998" />
        <geom name="right_behind_l_collision" pos="0 0 0" quat="1.0 0.0 0.0 0.0" type="mesh" mesh="right_behind_l.STL" class="collision" />
        <geom name="right_behind_l_visual" pos="0 0 0" quat="1.0 0.0 0.0 0.0" material="" type="mesh" mesh="right_behind_l.STL" class="visual" />
	<site name="right_behind__withfront_site" pos="-0.09673 -0.01571 0" size="0.01" rgba="1 0 0 1"/>

        <body name="right_behind_withwheel_l" pos="-0.212210040922846 -0.0345238834897212 0.0144999999995246" quat="1.0 0.0 0.0 0.0">
          <joint name="right_behind_withwheel_j" type="hinge" ref="0.0" class="motor" axis="0 0 1" range="-1.5 1"/>
          <inertial pos="0.0984942955452052 -0.0646236570438529 -0.00599780495653941" quat="1.0 0.0 0.0 0.0" mass="0.185679521185983" diaginertia="0.000586218654211056 0.00117687158971275 0.00175863230690654" />
          <geom name="right_behind_withwheel_l_collision" pos="0 0 0" quat="1.0 0.0 0.0 0.0" type="mesh" mesh="right_behind_withwheel_l.STL" class="collision" />
          <geom name="right_behind_withwheel_l_visual" pos="0 0 0" quat="1.0 0.0 0.0 0.0" material="" type="mesh" mesh="right_behind_withwheel_l.STL" class="visual" />
	  <site name="right_behind__withwheel_site" pos="-0.0461 0.04724 0" size="0.01" rgba="1 0 0 1"/>

          <body name="right_wheel_l" pos="0.214644166070022 -0.143149858441813 0.0210500000001512" quat="1.0 0.0 0.0 0.0">
            <joint name="right_wheel_j" type="hinge" ref="0.0" class="motor" axis="0 0 -1" />
            <inertial pos="-7.45422005260579E-05 0.000100591651953502 -0.00298506551089983" quat="1.0 0.0 0.0 0.0" mass="0.32373070940346" diaginertia="0.000298074526728345 0.00029837572331142 0.000520427202380742" />
            <geom name="right_wheel_l_collision" pos="0 0 0" quat="1.0 0.0 0.0 0.0" type="cylinder" size="0.06 0.02" class="collision" />
            <geom name="right_wheel_l_visual" pos="0 0 0" quat="1.0 0.0 0.0 0.0" material="" type="mesh" mesh="right_wheel_l.STL" class="visual" />
          </body>
        </body>
      </body>
      <body name="right_front_l" pos="0 -0.168000000000029 0.109926406870758" quat="0.7071067811865464 0.7071067811865488 0.0 0.0">
        <joint name="right_front_j" type="hinge" ref="0.0" class="motor" axis="0 0 -1" range="0 1.5" />
        <inertial pos="0.0405680515196211 -0.0058347489897399 0.00524456410707912" quat="1.0 0.0 0.0 0.0" mass="0.0394619339059221" diaginertia="5.0292088254302e-06 4.78273962136856e-05 5.21135509591296e-05" />
        <geom name="right_front_l_collision" pos="0 0 0" quat="1.0 0.0 0.0 0.0" type="mesh" mesh="right_front_l.STL" class="collision" />
        <geom name="right_front_l_visual" pos="0 0 0" quat="1.0 0.0 0.0 0.0" material="" type="mesh" mesh="right_front_l.STL" class="visual" />
        <body name="right_front_1_l" pos="0.0970018464954901 -0.0139514076882676 -0.00319999999999999" quat="1.0 0.0 0.0 0.0">
          <joint name="right_front_1_j" type="hinge" ref="0.0" class="motor" axis="0 0 -1" range="-0.5 1"/>
          <inertial pos="-0.0478331868898987 -0.0334383998387102 -0.00399092770729326" quat="1.0 0.0 0.0 0.0" mass="0.0174981792263048" diaginertia="9.70003460472124e-06 1.91505278420447e-05 2.86647012418916e-05" />
          <geom name="right_front_1_l_collision" pos="0 0 0" quat="1.0 0.0 0.0 0.0" type="mesh" mesh="right_front_1_l.STL" class="collision" />
          <geom name="right_front_1_l_visual" pos="0 0 0" quat="1.0 0.0 0.0 0.0" material="" type="mesh" mesh="right_front_1_l.STL" class="visual" />
          <body name="right_front_2_l" pos="-0.0958923382885917 -0.0670347630524708 0.00989999999973365" quat="1.0 0.0 0.0 0.0">
            <joint name="right_front_2_j" type="hinge" ref="0.0" class="motor" axis="0 0 1" range="-1 0.5"/>
            <inertial pos="-0.0736669481680574 0.0526595170277407 -0.00399999999961521" quat="1.0 0.0 0.0 0.0" mass="0.0370037657795749" diaginertia="4.85208977479004e-05 8.0967107895878e-05 0.000129093298808796" />
            <geom name="right_front_2_l_collision" pos="0 0 0" quat="1.0 0.0 0.0 0.0" type="mesh" mesh="right_front_2_l.STL" class="collision" />
            <geom name="right_front_2_l_visual" pos="0 0 0" quat="1.0 0.0 0.0 0.0" material="" type="mesh" mesh="right_front_2_l.STL" class="visual" />
	    <site name="right_front__withbehind_site" pos="-0.09784 0.06525 0" size="0.01" rgba="1 0 0 1"/>

            <body name="right_front_3_l" pos="-0.143933215613086 0.112485422517711 0" quat="1.0 0.0 0.0 0.0">
              <joint name="right_front_3_j" type="hinge" ref="0.0" class="motor" axis="0 0 1" />
              <inertial pos="-0.0576048087206504 -0.00937157212703932 -0.0138909277070416" quat="1.0 0.0 0.0 0.0" mass="0.0174981792263048" diaginertia="1.37714211622303e-06 2.74734203305429e-05 2.86647012418916e-05" />
              <geom name="right_front_3_l_collision" pos="0 0 0" quat="1.0 0.0 0.0 0.0" type="mesh" mesh="right_front_3_l.STL" class="collision" />
              <geom name="right_front_3_l_visual" pos="0 0 0" quat="1.0 0.0 0.0 0.0" material="" type="mesh" mesh="right_front_3_l.STL" class="visual" />
	      <site name="right_front__withwheel_site" pos="-0.11548 -0.01879 0" size="0.01" rgba="1 0 0 1"/>

            </body>
          </body>
        </body>
      </body>
      <body name="gimbal_yaw_l" pos="0 0 0.166000000000003" quat="1.0 0.0 0.0 0.0">
        <joint name="gimbal_yaw_j" type="hinge" ref="0.0" class="motor" axis="0 0 1" />
        <inertial pos="-0.0685278943755377 -0.0207639423722535 0.0706614035666273" quat="1.0 0.0 0.0 0.0" mass="0.670791042770214" diaginertia="0.000293377306677707 0.000538262472825082 0.00035095950828323" />
        <geom name="gimbal_yaw_l_collision" pos="0 0 0" quat="1.0 0.0 0.0 0.0" type="mesh" mesh="gimbal_yaw_l.STL" class="collision" />
        <geom name="gimbal_yaw_l_visual" pos="0 0 0" quat="1.0 0.0 0.0 0.0" material="" type="mesh" mesh="gimbal_yaw_l.STL" class="visual" />
	<site name="yaw_site" pos="-0.00327 0 0.10489" size="0.01" rgba="1 0 0 1"/>

        <body name="pitch_l" pos="-0.0768777510147372 -0.041910727257843 0.0495000000008742" quat="1.0 0.0 0.0 0.0">
          <joint name="pitch_j" type="hinge" ref="0.0" class="motor" axis="0.0501825596303518 -0.998740061632128 0" range="-0.7 0.5"/>
          <inertial pos="-0.0150769381773094 0.00168802698121073 0.00884956318473754" quat="1.0 0.0 0.0 0.0" mass="0.00354514237331588" diaginertia="2.54702032673678e-07 8.26793943458569e-07 5.89725087020952e-07" />
          <geom name="pitch_l_collision" pos="0 0 0" quat="1.0 0.0 0.0 0.0" type="mesh" mesh="pitch_l.STL" class="collision" />
          <geom name="pitch_l_visual" pos="0 0 0" quat="1.0 0.0 0.0 0.0" material="" type="mesh" mesh="pitch_l.STL" class="visual" />
          <body name="pitch_1_l" pos="-0.0339402750522404 -0.0107167122735374 0.0203521450379064" quat="1.0 0.0 0.0 0.0">
            <joint name="pitch_1_j" type="hinge" ref="0.0" class="motor" axis="-0.0501825596303165 0.998740061632129 0" range="-0.7 0.5"/>
            <inertial pos="0.0371789168053012 0.0043712407033658 0.0276969384561993" quat="1.0 0.0 0.0 0.0" mass="0.00578003763271066" diaginertia="1.75981495432595e-06 4.82906926938053e-06 3.10887459801507e-06" />
            <geom name="pitch_1_l_collision" pos="0 0 0" quat="1.0 0.0 0.0 0.0" type="mesh" mesh="pitch_1_l.STL" class="collision" />
            <geom name="pitch_1_l_visual" pos="0 0 0" quat="1.0 0.0 0.0 0.0" material="" type="mesh" mesh="pitch_1_l.STL" class="visual" />
            <body name="pitch_2_l" pos="0.0741571033773397 0.0127374416536399 0.0553938769131815" quat="1.0 0.0 0.0 0.0">
              <joint name="pitch_2_j" type="hinge" ref="0.0" class="motor" axis="-0.0501825596303165 0.998740061632129 0" range="-0.7 0.5"/>
              <inertial pos="0.071250753838725 0.0568626900502848 0.018131103620967" quat="1.0 0.0 0.0 0.0" mass="2.01000575288602" diaginertia="0.00109627675910609 0.00234702564713487 0.00186938031003329" />
              <geom name="pitch_2_l_collision" pos="0 0 0" quat="1.0 0.0 0.0 0.0" type="mesh" mesh="pitch_2_l.STL" class="collision" />
              <geom name="pitch_2_l_visual" pos="0 0 0" quat="1.0 0.0 0.0 0.0" material="" type="mesh" mesh="pitch_2_l.STL" class="visual" />
	     <site name="pitch_site" pos="0.03439 0 -0.02035" size="0.01" rgba="1 0 0 1"/>
            </body>
          </body>
        </body>
      </body>
      <site name="base_link_site" pos="0 0 0" quat="1 0 0 0" />
      <camera name="front_camera" mode="track" fovy="90.0" quat="4.329637285359678e-17 4.329637285359677e-17 0.7071067811865475 0.7071067811865476" pos="0.0 2.0 0.5" />
      <camera name="side_camera" mode="track" fovy="90.0" quat="-0.5 -0.4999999999999999 0.5 0.5000000000000001" pos="-2.0 0.0 0.5" />
    </body>
  </worldbody>

  <actuator>
    <motor name="left_front_j_ctrl" joint="left_front_j" class="motor" />
    <motor name="left_front_1_j_ctrl" joint="left_front_1_j" class="motor" />
    <motor name="left_front_2_j_ctrl" joint="left_front_2_j" class="motor" />
    <motor name="left_front_3_j_ctrl" joint="left_front_3_j" class="motor" />
    <motor name="left_behind_j_ctrl" joint="left_behind_j" class="motor" />
    <motor name="left_behind_withwheel_j_ctrl" joint="left_behind_withwheel_j" class="motor" />
    <motor name="left_wheel_j_ctrl" joint="left_wheel_j" class="motor" />
    <motor name="right_behind_j_ctrl" joint="right_behind_j" class="motor" />
    <motor name="right_behind_withwheel_j_ctrl" joint="right_behind_withwheel_j" class="motor" />
    <motor name="right_wheel_j_ctrl" joint="right_wheel_j" class="motor" />
    <motor name="right_front_j_ctrl" joint="right_front_j" class="motor" />
    <motor name="right_front_1_j_ctrl" joint="right_front_1_j" class="motor" />
    <motor name="right_front_2_j_ctrl" joint="right_front_2_j" class="motor" />
    <motor name="right_front_3_j_ctrl" joint="right_front_3_j" class="motor" />
    <motor name="gimbal_yaw_j_ctrl" joint="gimbal_yaw_j" class="motor" />
    <motor name="pitch_j_ctrl" joint="pitch_j" class="motor" />
    <motor name="pitch_1_j_ctrl" joint="pitch_1_j" class="motor" />
    <motor name="pitch_2_j_ctrl" joint="pitch_2_j" class="motor" />
  </actuator>

  <contact>
    <exclude body1="base_link" body2="left_front_l" />
    <exclude body1="left_front_l" body2="left_front_1_l" />
    <exclude body1="left_front_1_l" body2="left_front_2_l" />
    <exclude body1="left_front_2_l" body2="left_front_3_l" />
    <exclude body1="base_link" body2="left_behind_l" />
    <exclude body1="left_behind_l" body2="left_behind_withwheel_l" />
    <exclude body1="left_behind_withwheel_l" body2="left_wheel_l" />
    <exclude body1="base_link" body2="right_behind_l" />
    <exclude body1="right_behind_l" body2="right_behind_withwheel_l" />
    <exclude body1="right_behind_withwheel_l" body2="right_wheel_l" />
    <exclude body1="base_link" body2="right_front_l" />
    <exclude body1="right_front_l" body2="right_front_1_l" />
    <exclude body1="right_front_1_l" body2="right_front_2_l" />
    <exclude body1="right_front_2_l" body2="right_front_3_l" />
    <exclude body1="base_link" body2="gimbal_yaw_l" />
    <exclude body1="gimbal_yaw_l" body2="pitch_l" />
    <exclude body1="pitch_l" body2="pitch_1_l" />
    <exclude body1="pitch_1_l" body2="pitch_2_l" />
  </contact>

  <sensor>
    <framepos name="base_link_site_pos" objtype="site" objname="base_link_site" />
    <framequat name="base_link_site_quat" objtype="site" objname="base_link_site" />
    <framelinvel name="base_link_site_linvel" objtype="site" objname="base_link_site" />
    <frameangvel name="base_link_site_angvel" objtype="site" objname="base_link_site" />
    <velocimeter name="base_link_site_vel" site="base_link_site" />
    <accelerometer name="base_link_accel" site="base_link_site" />
    <gyro name="imu_gyro" site="base_link_site" />
  </sensor>


<equality>
    <connect site1="left_behind__withfront_site" site2="left_front__withbehind_site" solref="0.001 1" solimp="0.99 0.99 0.01"/>
    <connect site1="left_behind__withwheel_site" site2="left_front__withwheel_site" solref="0.001 1" solimp="0.99 0.99 0.01"/>
    <connect site1="right_behind__withwheel_site" site2="right_front__withwheel_site" solref="0.001 1" solimp="0.99 0.99 0.01"/>
    <connect site1="right_front__withbehind_site" site2="right_behind__withfront_site" solref="0.001 1" solimp="0.99 0.99 0.01"/>
    <connect site1="yaw_site" site2="pitch_site" solref="0.001 1" solimp="0.99 0.99 0.01"/>
</equality>


</mujoco>
